Workbook

Sheet Read Me
A1: GCC School / KC GlobEd — In-house CRM
A2: Scope of work split into 3 phases · priorities · user stories · v1.0 · September 2026
A4: What this is | B4: Every feature from 'Inhouse CRM Req.List_V1' (270 features, 20 modules) placed into one of three delivery phases, with a Must / Should / Could priority, the user it serves, and a plain user story. Ten features were added for the plug-and-play access model and the testing-platform link — they carry NEW-xx IDs.
A5: How to use it | B5: 1. 'Phase Plan' — what each phase delivers and why. 2. 'Summary' — live counts by phase, priority and module. 3. 'Requirements' — the full list; filter by Phase or Module to build a sprint backlog. 4. 'Student Panel' — everything the candidate sees. 5. 'Roles & Access' — how super admin switches features on per user. 6. 'Candidate Journey' — the agreed lead-to-interview flow mapped to features. 7. 'Open Questions' — decisions that block work.
A6: Priority | B6: Must = the phase cannot go live without it · Should (can do) = plan it into the phase, drop only under pressure · Could = nice to have, first thing to defer.
A7: Phase in one line each | B7: Phase 1 — run the agreed journey end to end for real candidates. Phase 2 — automate, integrate the dialer and loans, and give managers proper reporting. Phase 3 — intelligence, remarketing, mobile and optimisation.
A8: Access model | B8: Roles are not hard-coded. Super admin creates a user, then ticks the modules, menus, fields, actions and data scope that user gets. Templates (Counsellor, Team Leader, Marketing, Finance, Support, Interviewer) are just saved tick-sets — see 'Roles & Access'.
A9: Sources used | B9: Inhouse CRM Req.List_V1.xlsx (the 270-feature list) · the agreed Lead-to-Interview journey (MOM 10 Sep 2026, Meritto ticket 277803) · the in-house CRM B2C requirements SOW v1.0.
A10: What is assumed | B10: Phase placement and priorities are a proposal for the tech team and leadership to confirm. Nothing here changes the feature descriptions from the V1 list — those are carried through word for word.
A11: Not included | B11: Effort estimates in person-days, costs, wireframes, database design, and B2B / placement / corporate L&D scope.

Sheet Requirements
A1: 270 features from the V1 list + 10 added (NEW-xx). Filter Phase or Module to build the sprint backlog.
A2: ID | B2: Module | C2: Feature | D2: What it does (from V1 list) | E2: Phase | F2: Priority | G2: Main user | H2: User story | I2: Frontend Timeline | J2: Start Date | K2: End Date | L2: Backend Timeline | M2: Start Date | N2: End Date
A3: 1 | B3: Admin & User Management | C3: User & Team Management | D3: Create, edit, activate/deactivate and manage all CRM users and internal teams. | E3: Phase 1 | F3: Must | G3: Super Admin | H3: As a super admin I want to create, edit and deactivate CRM users so that only current staff can log in. | I3: 1st Week | J3: 16/09/2026 | K3: 23/09/2026 | L3: 1 week | M3: 16/09/2026 | N3: 23/09/2026
A4: 2 | C4: Default Role-Based Access | D4: Provide predefined permissions for Admin, Manager, Counsellor, Marketing, Finance, HR, Support and Tech users. | E4: Phase 1 | F4: Must | G4: Super Admin | H4: As a super admin I want ready-made role templates (counsellor, team leader, marketing, finance) so that a new user is set up in minutes.
A5: 3 | C5: Custom Role-Based Access | D5: Allow GCC School to create custom roles with module, action and data-level permissions. | E5: Phase 1 | F5: Must | G5: Super Admin | H5: As a super admin I want to build a custom role by ticking the modules, actions and data a user may access so that each person sees only what their job needs.
A6: 4 | C6: Teams & Hierarchy Management | D6: Configure departments, reporting managers, teams, counsellor groups and organisational hierarchy. | E6: Phase 1 | F6: Must | G6: Super Admin | H6: As a super admin I want to set up teams, reporting managers and counsellor groups so that leads and dashboards follow our hierarchy.
A7: 5 | C7: Data Masking | D7: Mask mobile, email, payment and other sensitive candidate information based on role. | E7: Phase 1 | F7: Should | G7: Super Admin | H7: As a super admin I want to mask mobile, email and payment details for chosen roles so that candidate data is not exposed unnecessarily.
A8: 6 | C8: User Session & Audit Log | D8: Track login, logout, session activity, important actions and security events. | E8: Phase 1 | F8: Must | G8: Super Admin | H8: As a super admin I want a log of logins, sessions and key actions so that I can investigate any misuse.
A9: 7 | C9: Access Control by Team | D9: Restrict records and dashboards based on team, location, program or reporting hierarchy. | E9: Phase 1 | F9: Must | G9: Team Leader | H9: As a team leader I want my team to see only their own leads and dashboards so that data stays within the right team.
A10: 8 | C10: Bulk User Management | D10: Upload, update or deactivate multiple CRM users through bulk operations. | E10: Phase 2 | F10: Should | G10: Super Admin | H10: As a super admin I want to add or deactivate many users at once so that onboarding a new batch of counsellors is quick.
A11: 9 | C11: Configuration Management | D11: Allow authorised admins to configure stages, fields, templates, rules, notifications and business parameters. | E11: Phase 1 | F11: Must | G11: Super Admin | H11: As a super admin I want to configure stages, fields, templates and rules myself so that small changes do not need the tech team.
A12: 10 | B12: Lead Management | C12: Multi-Source Lead Capture | D12: Capture leads from website, landing pages, Meta, Google, portals, referrals, channel partners, events and other approved sources. | E12: Phase 1 | F12: Must | G12: Marketing | H12: As a marketing manager I want every lead from website, Meta, Google, partners and events to land in the CRM so that nothing is lost. | I12: 2nd Week | J12: 24/09/2026 | K12: 46032 | L12: 2 Weeks | M12: 24/09/2026 | N12: 46032
A13: 11 | C13: Multi-Step Enquiry Form | D13: Provide configurable multi-step forms with different fields and validations at each stage. | E13: Phase 1 | F13: Must | G13: Marketing | H13: As a marketing manager I want a multi-step enquiry form with different fields per step so that we ask only what is needed at each stage.
A14: 12 | C14: Quick Add Lead | D14: Allow counsellors/admins to manually create a lead from the CRM. | E14: Phase 1 | F14: Must | G14: Counsellor | H14: As a counsellor I want to add a lead manually so that walk-ins and phone enquiries are captured.
A15: 13 | C15: Bulk Lead Upload | D15: Upload large lead databases through CSV/XLSX with field mapping, validation and error reporting. | E15: Phase 1 | F15: Must | G15: Admin | H15: As an admin I want to upload a lead file with field mapping and an error report so that bulk databases load cleanly.
A16: 14 | C16: Bulk Lead Update | D16: Update owner, stage, source, tags and other permitted fields for multiple leads at once. | E16: Phase 2 | F16: Should | G16: Team Leader | H16: As a team leader I want to update owner, stage or tags for many leads at once so that reallocation is not one by one.
A17: 15 | C17: Custom Fields | D17: Create GCC School-specific fields without requiring code changes. | E17: Phase 1 | F17: Must | G17: Super Admin | H17: As a super admin I want to add our own fields without code so that the CRM matches how we work.
A18: 16 | C18: Duplicate Blocking | D18: Identify duplicate leads using mobile, email and other matching rules before creation. | E18: Phase 1 | F18: Must | G18: Admin | H18: As an admin I want duplicates blocked on mobile and email so that two counsellors never call the same candidate.
A19: 17 | C19: Duplicate Merge | D19: Allow authorised users to merge duplicate records while preserving the complete activity history. | E19: Phase 2 | F19: Should | G19: Team Leader | H19: As a team leader I want to merge duplicate records while keeping the full history so that the candidate has one clean profile.
A20: 18 | C20: Lead Verification | D20: Verify candidate contact details through email/OTP or configured verification methods. | E20: Phase 1 | F20: Must | G20: Marketing | H20: As a marketing manager I want contact details verified by OTP or email so that we spend time on real leads.
A21: 19 | C21: Lead Source Tracking | D21: Track the original and latest source of every lead throughout the lifecycle. | E21: Phase 1 | F21: Must | G21: Marketing | H21: As a marketing manager I want the first and latest source stored on every lead so that credit is assigned correctly.
A22: 20 | C22: UTM Tracking | D22: Capture UTM source, medium, campaign, term, content and landing-page details. | E22: Phase 1 | F22: Must | G22: Marketing | H22: As a marketing manager I want UTM source, medium, campaign, term, content and landing page captured so that ad spend can be judged.
A23: 21 | C23: Referral & Partner Tracking | D23: Capture referral code, partner name, partner link and partner-specific attribution. | E23: Phase 1 | F23: Must | G23: Marketing | H23: As a marketing manager I want referral code, partner name and partner link captured so that channel partner leads are attributed.
A24: 22 | C24: Facebook Lead Ad Connector | D24: Automatically push Meta/Facebook leads into the CRM. | E24: Phase 1 | F24: Must | G24: Marketing | H24: As a marketing manager I want Meta lead-form leads pushed in automatically so that response time is in minutes, not hours.
... A34: 32 | C34: Lead Export | D34: Export authorised lead data to Excel/CSV based on filters and permissions. | E34: Phase 1 | F34: Should | G34: Team Leader | H34: As a team leader I want to export the leads I am allowed to see so that offline analysis is possible.
A35: 33 | B35: Marketing & Acquisition | C35: Source Master | D35: Maintain a central master of paid, organic, referral, partner, event, portal and other lead sources. | E35: Phase 1 | F35: Must | G35: Marketing | H35: As a marketing manager I want one master list of sources so that reporting is consistent everywhere. | I35: 3rd Week | J35: 46152 | K35: 46366 | L35: 3rd week | M35: 46152 | N35: 46366
A36: 34 | C36: Channel Classification | D36: Group sources into standard channels such as Paid, Organic, Referral, Partner, Direct and Other. | E36: Phase 1 | F36: Should | G36: Marketing | H36: As a marketing manager I want sources grouped into paid, organic, referral, partner and direct so that channel performance is comparable.
A37: 35 | C37: Campaign Master | D37: Create campaigns with source, channel, program, dates, budget and campaign identifiers. | E37: Phase 2 | F37: Must | G37: Marketing | H37: As a marketing manager I want to create campaigns with source, program, dates and budget so that spend maps to results.
A38: 36 | C38: Campaign Dashboard | D38: Track leads, qualified leads, applications, interviews, payments and admissions by campaign. | E38: Phase 2 | F38: Must | G38: Marketing | H38: As a marketing manager I want a campaign dashboard showing leads through to admissions so that I can shift budget quickly.
A39: 37 | C39: Source Performance Report | D39: Compare conversion and quality across sources and campaigns. | E39: Phase 2 | F39: Must | G39: Marketing | H39: As a marketing manager I want a source performance report so that I know which channel brings quality, not just volume.
A40: 38 | C40: First-Touch Attribution | D40: Preserve the original source that generated the candidate. | E40: Phase 1 | F40: Must | G40: Marketing | H40: As a marketing manager I want the original source preserved so that later activity does not overwrite where the candidate came from.
A41: 39 | C41: Latest-Touch Attribution | D41: Capture the latest marketing interaction/source before conversion. | E41: Phase 2 | F41: Should | G41: Marketing | H41: As a marketing manager I want the latest touch before conversion recorded so that both attribution models are available.
A42: 40 | C42: UTM-to-Lead Mapping | D42: Store digital campaign parameters directly against the lead and application. | E42: Phase 1 | F42: Must | G42: Marketing | H42: As a marketing manager I want UTM values stored against lead and application so that campaign reporting runs end to end.
A43: 41 | C43: Landing Page Attribution | D43: Track which landing page/form generated each candidate. | E43: Phase 1 | F43: Should | G43: Marketing | H43: As a marketing manager I want to know which landing page produced each lead so that pages can be compared.
A44: 42 | C44: Conversion Tags Integration | D44: Support conversion/event tags for approved marketing platforms. | E44: Phase 2 | F44: Must | G44: Marketing | H44: As a marketing manager I want conversion events sent to the ad platforms so that campaigns optimise on real outcomes.
A45: 43 | C45: Facebook Remarketing Connector | D45: Send eligible audiences/events to Meta remarketing workflows. | E45: Phase 3 | F45: Could | G45: Marketing | H45: As a marketing manager I want remarketing audiences pushed to Meta so that warm leads can be retargeted.
A46: 44 | C46: Google Remarketing Connector | D46: Send eligible audiences/events to Google remarketing workflows. | E46: Phase 3 | F46: Could | G46: Marketing | H46: As a marketing manager I want remarketing audiences pushed to Google so that warm leads can be retargeted.
A47: 45 | C47: Audience Segmentation | D47: Build audiences based on source, stage, program, geography, score, payment and engagement. | E47: Phase 2 | F47: Should | G47: Marketing | H47: As a marketing manager I want to build audiences by source, stage, program, score and payment status so that messaging is targeted.
... A52: 50 | C52: Marketing ROI View | D52: Compare campaign investment, lead volume, conversion and revenue/admission outcomes where cost data is available. | E52: Phase 3 | F52: Should | G52: Leadership | H52: As a leader I want campaign cost against conversions and admissions so that marketing ROI is clear.
A53: 51 | B53: Communication | C53: Email Communication | D53: Send transactional, operational and nurture emails directly from the CRM. | E53: Phase 1 | F53: Must | G53: Counsellor | H53: As a counsellor I want to send emails from the CRM so that every message is logged against the candidate. | I53: 4th week | J53: 13/10/2026 | K53: 20/10/2026 | L53: 4th week | M53: 13/10/2026 | N53: 20/10/2026
...

Sheet Summary
A1: Scope summary
A2: Live counts from the Requirements tab — they update if rows are added or edited.
A4: Features by phase and priority
A5: Phase | B5: Must | C5: Should | D5: Could | E5: Total
A6: Phase 1 | B6: =COUNTIFS(Requirements!$E$3:$E$229,$A6,Requirements!$F$3:$F$229,B$5) -> 114 | C6: =COUNTIFS(Requirements!$E$3:$E$229,$A6,Requirements!$F$3:$F$229,C$5) -> 15 | D6: =COUNTIFS(Requirements!$E$3:$E$229,$A6,Requirements!$F$3:$F$229,D$5) -> 0 | E6: =SUM(B6:D6) -> 129
A7: Phase 2 | B7: =COUNTIFS(Requirements!$E$3:$E$229,$A7,Requirements!$F$3:$F$229,B$5) -> 26 | C7: =COUNTIFS(Requirements!$E$3:$E$229,$A7,Requirements!$F$3:$F$229,C$5) -> 51 | D7: =COUNTIFS(Requirements!$E$3:$E$229,$A7,Requirements!$F$3:$F$229,D$5) -> 1 | E7: =SUM(B7:D7) -> 78
A8: Phase 3 | B8: =COUNTIFS(Requirements!$E$3:$E$229,$A8,Requirements!$F$3:$F$229,B$5) -> 0 | C8: =COUNTIFS(Requirements!$E$3:$E$229,$A8,Requirements!$F$3:$F$229,C$5) -> 3 | D8: =COUNTIFS(Requirements!$E$3:$E$229,$A8,Requirements!$F$3:$F$229,D$5) -> 17 | E8: =SUM(B8:D8) -> 20
A9: Total | B9: =SUM(B6:B8) -> 140 | C9: =SUM(C6:C8) -> 69 | D9: =SUM(D6:D8) -> 18 | E9: =SUM(E6:E8) -> 227
A11: Features by module
A12: Module | B12: Phase 1 | C12: Phase 2 | D12: Phase 3 | E12: Total
A13: Admin & User Management | B13: =COUNTIFS(Requirements!$B$3:$B$229,$A13,Requirements!$E$3:$E$229,"Phase 1") -> 1 | C13: =COUNTIFS(Requirements!$B$3:$B$229,$A13,Requirements!$E$3:$E$229,"Phase 2") -> 0 | D13: =COUNTIFS(Requirements!$B$3:$B$229,$A13,Requirements!$E$3:$E$229,"Phase 3") -> 0 | E13: =SUM(B13:D13) -> 1
A14: Lead Management | B14: =COUNTIFS(Requirements!$B$3:$B$229,$A14,Requirements!$E$3:$E$229,"Phase 1") -> 1 | C14: =COUNTIFS(Requirements!$B$3:$B$229,$A14,Requirements!$E$3:$E$229,"Phase 2") -> 0 | D14: =COUNTIFS(Requirements!$B$3:$B$229,$A14,Requirements!$E$3:$E$229,"Phase 3") -> 0 | E14: =SUM(B14:D14) -> 1
A15: Marketing & Acquisition | B15: =COUNTIFS(Requirements!$B$3:$B$229,$A15,Requirements!$E$3:$E$229,"Phase 1") -> 1 | C15: =COUNTIFS(Requirements!$B$3:$B$229,$A15,Requirements!$E$3:$E$229,"Phase 2") -> 0 | D15: =COUNTIFS(Requirements!$B$3:$B$229,$A15,Requirements!$E$3:$E$229,"Phase 3") -> 0 | E15: =SUM(B15:D15) -> 1
A16: Communication | B16: =COUNTIFS(Requirements!$B$3:$B$229,$A16,Requirements!$E$3:$E$229,"Phase 1") -> 1 | C16: =COUNTIFS(Requirements!$B$3:$B$229,$A16,Requirements!$E$3:$E$229,"Phase 2") -> 0 | D16: =COUNTIFS(Requirements!$B$3:$B$229,$A16,Requirements!$E$3:$E$229,"Phase 3") -> 0 | E16: =SUM(B16:D16) -> 1
A17: Counsellor & Sales | B17: =COUNTIFS(Requirements!$B$3:$B$229,$A17,Requirements!$E$3:$E$229,"Phase 1") -> 1 | C17: =COUNTIFS(Requirements!$B$3:$B$229,$A17,Requirements!$E$3:$E$229,"Phase 2") -> 0 | D17: =COUNTIFS(Requirements!$B$3:$B$229,$A17,Requirements!$E$3:$E$229,"Phase 3") -> 0 | E17: =SUM(B17:D17) -> 1
A18: Application & Student Journey | B18: =COUNTIFS(Requirements!$B$3:$B$229,$A18,Requirements!$E$3:$E$229,"Phase 1") -> 1 | C18: =COUNTIFS(Requirements!$B$3:$B$229,$A18,Requirements!$E$3:$E$229,"Phase 2") -> 0 | D18: =COUNTIFS(Requirements!$B$3:$B$229,$A18,Requirements!$E$3:$E$229,"Phase 3") -> 0 | E18: =SUM(B18:D18) -> 1
A19: Program & Eligibility | B19: =COUNTIFS(Requirements!$B$3:$B$229,$A19,Requirements!$E$3:$E$229,"Phase 1") -> 5 | C19: =COUNTIFS(Requirements!$B$3:$B$229,$A19,Requirements!$E$3:$E$229,"Phase 2") -> 2 | D19: =COUNTIFS(Requirements!$B$3:$B$229,$A19,Requirements!$E$3:$E$229,"Phase 3") -> 0 | E19: =SUM(B19:D19) -> 7
A20: Examination / NFET / Aon | B20: =COUNTIFS(Requirements!$B$3:$B$229,$A20,Requirements!$E$3:$E$229,"Phase 1") -> 9 | C20: =COUNTIFS(Requirements!$B$3:$B$229,$A20,Requirements!$E$3:$E$229,"Phase 2") -> 3 | D20: =COUNTIFS(Requirements!$B$3:$B$229,$A20,Requirements!$E$3:$E$229,"Phase 3") -> 0 | E20: =SUM(B20:D20) -> 12
A21: Interview & Selection | B21: =COUNTIFS(Requirements!$B$3:$B$229,$A21,Requirements!$E$3:$E$229,"Phase 1") -> 8 | C21: =COUNTIFS(Requirements!$B$3:$B$229,$A21,Requirements!$E$3:$E$229,"Phase 2") -> 0 | D21: =COUNTIFS(Requirements!$B$3:$B$229,$A21,Requirements!$E$3:$E$229,"Phase 3") -> 1 | E21: =SUM(B21:D21) -> 9
A22: Offer & Admission | B22: =COUNTIFS(Requirements!$B$3:$B$229,$A22,Requirements!$E$3:$E$229,"Phase 1") -> 6 | C22: =COUNTIFS(Requirements!$B$3:$B$229,$A22,Requirements!$E$3:$E$229,"Phase 2") -> 2 | D22: =COUNTIFS(Requirements!$B$3:$B$229,$A22,Requirements!$E$3:$E$229,"Phase 3") -> 0 | E22: =SUM(B22:D22) -> 8
A23: Payment Management | B23: =COUNTIFS(Requirements!$B$3:$B$229,$A23,Requirements!$E$3:$E$229,"Phase 1") -> 11 | C23: =COUNTIFS(Requirements!$B$3:$B$229,$A23,Requirements!$E$3:$E$229,"Phase 2") -> 5 | D23: =COUNTIFS(Requirements!$B$3:$B$229,$A23,Requirements!$E$3:$E$229,"Phase 3") -> 1 | E23: =SUM(B23:D23) -> 17
A24: Education Loan | B24: =COUNTIFS(Requirements!$B$3:$B$229,$A24,Requirements!$E$3:$E$229,"Phase 1") -> 0 | C24: =COUNTIFS(Requirements!$B$3:$B$229,$A24,Requirements!$E$3:$E$229,"Phase 2") -> 10 | D24: =COUNTIFS(Requirements!$B$3:$B$229,$A24,Requirements!$E$3:$E$229,"Phase 3") -> 1 | E24: =SUM(B24:D24) -> 11
... A32: Masters & Data Management | B32: =COUNTIFS(Requirements!$B$3:$B$229,$A32,Requirements!$E$3:$E$229,"Phase 1") -> 0 | C32: =COUNTIFS(Requirements!$B$3:$B$229,$A32,Requirements!$E$3:$E$229,"Phase 2") -> 0 | D32: =COUNTIFS(Requirements!$B$3:$B$229,$A32,Requirements!$E$3:$E$229,"Phase 3") -> 0 | E32: =SUM(B32:D32) -> 0
A33: Total | B33: =SUM(B13:B32) -> 67 | C33: =SUM(C13:C32) -> 41 | D33: =SUM(D13:D32) -> 7 | E33: =SUM(E13:E32) -> 115
A35: Student-panel features | B35: =COUNTIF(Requirements!$G$3:$G$229,"Student") -> 30
A36: Features added beyond the V1 list | B36: =COUNTIF(Requirements!$A$3:$A$229,"NEW-*") -> 0

Sheet Phase Plan
A1: Timings are indicative and to be confirmed with the tech team — the phase content is the decision that matters.
A2: Phase | B2: Theme | C2: What is built | D2: What it means for the business | E2: Exit condition
A3: Phase 1 | B3: Run the journey | C3: Everything needed to run the agreed lead-to-interview journey for real candidates: user & access setup, lead capture from ads and partners, counsellor allocation and calling basics, the student panel with application and documents, NFET payment gate with the exam link, interview, offer and the core payments, plus core notifications, reports, masters and security. | D3: A paid-ad lead and a partner lead can both be captured, counselled, examined, interviewed, selected and admitted entirely inside the CRM. | E3: Go-live on one live intake cycle.
A4: Phase 2 | B4: Automate and scale | C4: Marketing campaigns and attribution reporting, the full communication suite (email/SMS/WhatsApp campaigns and automation), the automation rule builder, dialer integration with call reporting, lead scoring and SLA escalation, education loan module, advanced payments (installments, discounts, refunds), document manager, support/query desk, and manager dashboards. | D4: Counsellors stop doing manual follow-up, managers get daily performance data, and financing is tracked in one place. | E4: Two cycles running with automation and no manual chasing.
A5: Phase 3 | B5: Optimise | C5: Predictive lead strength, remarketing connectors, marketing ROI and MEI views, real-time and scheduled reporting, WhatsApp bot, recurring nurture and re-engagement, mobile CRM, predictive and power dialing, and the remaining advanced integrations. | D5: Marketing spend is optimised on outcomes and the team can work away from the desk. | E5: Continuous improvement, not a fixed end date.

Sheet Student Panel
A1: Everything the candidate sees and does in their own panel. Sections can be switched on or off per program (NEW-09).
A2: ID | B2: Feature | C2: What the candidate gets | D2: Phase | E2: Priority | F2: User story
A3: 102 | B3: Applicant Registration | C3: Allow candidates to register from website, ads, partner links or other approved entry points. | D3: Phase 1 | E3: Must | F3: As a candidate I want to register from the website, an ad or a partner link so that I can start my application immediately.
A4: 103 | B4: Email Verification | C4: Verify candidate email before enabling the application journey where required. | D4: Phase 1 | E4: Must | F4: As a candidate I want my email verified so that I receive every update about my application.
A5: 104 | B5: OTP Login | C5: Allow candidates to securely log in using OTP. | D5: Phase 1 | E5: Must | F5: As a candidate I want to log in with an OTP so that I do not need to remember a password.
A6: 105 | B6: Application Number Login | C6: Support application-number based login where required. | D6: Phase 1 | E6: Should | F6: As a candidate I want to log in with my application number so that I can return to my application easily.
A7: 106 | B7: Personalised Student Dashboard | C7: Provide each applicant with a dashboard showing application status, tasks, documents, exams, payments and communications. | D7: Phase 1 | E7: Must | F7: As a candidate I want a dashboard showing status, pending tasks, documents, exam and payments so that I always know where I stand.
A8: 107 | B8: Application Progress Tracker | C8: Show candidates exactly which application steps are completed, pending or blocked. | D8: Phase 1 | E8: Must | F8: As a candidate I want to see which steps are done, pending or blocked so that I know exactly what to do next.
A9: 108 | B9: Multi-Step Application Form | C9: Capture required personal, academic, professional and program information in structured steps. | D9: Phase 1 | E9: Must | F9: As a candidate I want the application split into clear steps so that a long form does not feel overwhelming.
A10: 109 | B10: Form Save & Resume | C10: Allow candidates to save incomplete applications and continue later. | D10: Phase 1 | E10: Must | F10: As a candidate I want to save and resume my application so that I can finish it when documents are at hand.
A11: 110 | B11: Final Declaration & Submission | C11: Require final declaration before the application is formally submitted. | D11: Phase 1 | E11: Must | F11: As a candidate I want to make a final declaration before submitting so that I confirm my information is correct.
A12: 111 | B12: Document Upload | C12: Allow candidates to upload KYC, marksheets, academic and eligibility documents. | D12: Phase 1 | E12: Must | F12: As a candidate I want to upload KYC and marksheets so that my eligibility can be checked.
A13: 114 | B13: Application Status | C13: Display current application status and next required action. | D13: Phase 1 | E13: Must | F13: As a candidate I want to see my application status and next required action so that I am never left guessing.
... A33: 254 | B33: Candidate Dashboard | C33: Provide a personalised dashboard as the common destination for candidate journeys. | D33: Phase 1 | E33: Must | F33: As a candidate I want one dashboard as my destination after registration so that everything I need is in one place.

Sheet Roles & Access
A1: These are DEFAULT TEMPLATES, not fixed roles. Super admin can switch any line on or off for any individual user (NEW-01 to NEW-08).
A2: Capability | B2: Super Admin | C2: Admissions Admin | D2: Team Leader | E2: Counsellor | F2: Marketing | G2: Finance | H2: Interviewer | I2: Student
A3: Manage organisation settings & masters | B3: Full | C3: View | D3: - | E3: - | F3: - | G3: - | H3: - | I3: -
A4: Create users & set permissions | B4: Full | C4: - | D4: - | E4: - | F4: - | G4: - | H4: - | I4: -
A5: Lead list & 360 profile | B5: All | C5: All | D5: Team | E5: Own | F5: All (read) | G5: - | H5: - | I5: -
A6: Add / import leads | B6: Full | C6: Full | D6: Full | E6: Add only | F6: Import | G6: - | H6: - | I6: -
A7: Reassign leads | B7: Full | C7: Full | D7: Team | E7: - | F7: - | G7: - | H7: - | I7: -
A8: Call, WhatsApp, email a candidate | B8: Full | C8: Full | D8: Team | E8: Own | F8: - | G8: - | H8: - | I8: -
A9: Tasks & follow-ups | B9: Full | C9: Full | D9: Team | E9: Own | F9: - | G9: - | H9: - | I9: -
A10: Campaigns, sources & attribution | B10: Full | C10: View | D10: View | E10: - | F10: Full | G10: - | H10: - | I10: -
A11: Communication templates | B11: Full | C11: View | D11: - | E11: - | F11: Full | G11: - | H11: - | I11: -
A12: Automation rules | B12: Full | C12: View | D12: - | E12: - | F12: Propose | G12: - | H12: - | I12: -
A13: Application & document verification | B13: Full | C13: Full | D13: View | E13: View | F13: - | G13: - | H13: - | I13: -
... A25: Audit & permission logs | B25: Full | C25: View | D25: - | E25: - | F25: - | G25: - | H25: - | I25: -
A28: How the plug-and-play permission builder works
A29: Step | B29: Action | C29: Detail
A30: 1 | B30: Create the user | C30: Name, email, mobile, team, reporting manager, login method.
A31: 2 | B31: Pick a template or start blank | C31: Counsellor, Senior Counsellor, Team Leader, Marketing, Finance, Support, Interviewer — or none.
A32: 3 | B32: Tick the modules | C32: Only ticked modules appear in that user's menu; the rest are hidden, not greyed out.
A33: 4 | B33: Tick the actions | C33: View, create, edit, delete, export, reassign, approve — separately per module.
A34: 5 | B34: Set the data scope | C34: Own records / team / location / program / cohort / all.
A35: 6 | B35: Set field visibility | C35: Hide or make read-only any sensitive field, e.g. payment details or full mobile number.
A36: 7 | B36: Preview and save | C36: See the CRM exactly as that user will see it, then save. Every change is logged.

Sheet Candidate Journey
A1: The agreed lead-to-interview journey (MOM 10 Sep 2026, ticket 277803). Steps ending 'a' are the paid-ads track, 'b' the channel-partner track.
A2: Step | B2: Stage | C2: What happens | D2: CRM features that deliver it | E2: Feature IDs | F2: Phase
A3: J-01 | B3: Lead arrives | C3: Paid ads lead (Meta / Google) or channel partner lead via referral link + UTM code | D3: Multi-source capture, UTM tracking, partner attribution, duplicate blocking | E3: 10, 20, 21, 16, 22, 23 | F3: Phase 1
A4: J-02 | B4: Enquiry form | C4: Multi-step enquiry form — long form for paid ads, short form for partner leads | D4: Multi-step enquiry form, custom fields, lead verification | E4: 11, 15, 18 | F4: Phase 1
A5: J-03 | B5: Application-success message | C5: Confirmation communication triggered automatically on submission | D5: Stage-based communication, email/SMS/WhatsApp templates | E5: 187, 51, 59, 61 | F5: Phase 1
A6: J-04 | B6: Dashboard credentials | C6: Login details shared with the candidate | D6: OTP login, application number login, automated communication | E6: 104, 105, 199 | F6: Phase 1
A7: J-05 | B7: Candidate dashboard | C7: Candidate lands on a personalised dashboard — the common destination for both tracks | D7: Personalised student dashboard, progress tracker | E7: 106, 107, 254 | F7: Phase 1
A8: J-06a | B8: Paid ads track — full application | C8: ~17-section application form; no NFET in the initial journey | D8: Multi-step application form, save & resume, final declaration | E8: 108, 109, 110, 251 | F8: Phase 1
A9: J-06b | B9: Partner track — personal info + NFET fee | C9: Personal information, then NFET fee payment | D9: NFET fee collection, dynamic payment enablement, payment retry | E9: 157, 160, 167, 252 | F9: Phase 1
A10: J-07b | B10: Exam unlocked | C10: Aon exam unlocked after payment — slot booking and mock tests inside the dashboard | D10: NFET payment gate, exam integration, slot booking, mock test | E10: 126, 127, 128, 130 | F10: Phase 1
A11: J-08b | B11: Exam completed | C11: Score captured in the CRM in real time | D11: Exam completion status, real-time result capture, scorecard | E11: 131, 132, 133 | F11: Phase 1
A12: J-09b | B12: Counsellor review | C12: Counsellor reviews the candidate on score plus profile | D12: Score-based eligibility, manual override, candidate profiling | E12: 135, 136, 124 | F12: Phase 1
A13: J-10a | B13: Document upload & KYC | C13: Marksheets and KYC uploaded, eligibility checked | D13: Document upload, document verification, eligibility verification | E13: 111, 112, 123 | F13: Phase 1
... A18: J-15 | B18: Admission & loan | C18: Programme fee or education loan, then final admission status | D18: Programme fee, loan tracking, final admission status | E18: 159, 172, 177, 259 | F18: Phase 2

Sheet Open Questions
A1: ID | B1: Question | C1: Why it matters | D1: Owner | E1: Needed by
A2: Q-01 | B2: Is the existing Meritto instance replaced, or does the in-house CRM run alongside it first? | C2: Decides migration scope, data porting and go-live risk | D2: Leadership | E2: Before Phase 1 build
A3: Q-02 | B3: Do paid-ad candidates ever take the NFET later in the journey? | C3: The agreed flow says no NFET in the initial journey — the stage model depends on it | D3: Product Owner | E3: Phase 1 design
A4: Q-03 | B4: Which payment gateway, and who owns the merchant account? | C4: Blocks the NFET fee gate, the core of the partner track | D4: Finance | E4: Phase 1 sprint 2
A5: Q-04 | B5: Aon / Merittrac integration: API or file exchange, and who provides credentials? | C5: Determines whether results are real-time or batch | D5: Tech Lead | E5: Phase 1 sprint 2
A6: Q-05 | B6: Which dialer, and is it integrated in Phase 1 or Phase 2? | C6: Call capture, recordings and productivity reporting depend on it | D6: Inside Sales head | E6: Phase 1 gate
A7: Q-06 | B7: What are the exact lead stages and dispositions we will use? | C7: Every report, automation and dashboard is built on this list | D7: Product Owner | E7: Phase 1 sprint 1
A8: Q-07 | B8: Round-robin rules: pure rotation, or weighted by workload, language or program? | C8: Changes the distribution engine design | D8: Inside Sales head | E8: Phase 1 sprint 1
A9: Q-08 | B9: Which fields must be masked, and from which roles? | C9: Drives the field-level permission build and DPDP posture | D9: Legal + Super Admin | E9: Phase 1 design
A10: Q-09 | B10: WhatsApp: which BSP, and are templates already approved? | C10: Approval lead times can delay automation in Phase 2 | D10: Marketing | E10: Phase 1 gate
A11: Q-10 | B11: Loan partners at launch — Credila only, or more? | C11: Sizes the Phase 2 loan module | D11: Finance | E11: Phase 2 start
A12: Q-11 | B12: How long do we retain call recordings, documents and candidate data? | C12: DPDP retention and storage cost | D12: Legal | E12: Phase 1 design
... A14: Q-13 | B14: Who is the named Product Owner for day-to-day decisions? | C14: Sprint pace depends on someone answering these questions quickly | D14: Leadership | E14: Before Phase 1 build
